Workbook

Sheet Cover
B10: Financial Model (36 months)
B12: Three scenarios (Conservative, Base, High-growth) driven from one assumptions sheet. Change the scenario selector on the Assumptions sheet. Nothing here is an actual; all figures are scenario outputs.
B16: Prepared for | C16: The Founder, Vytalix
B17: Date | C17: 8 September 2026
B18: Version | C18: 1.0 · Confidential draft
B20: Contents
B21: README
B22: Assumptions
B23: Revenue build
B24: Cost of sales
B25: Opex
B26: Headcount
B27: P&L
B28: Cash flow
B29: Funding requirement
B30: Dashboard
B31: Sensitivity
... B35: Colour code: yellow cells are inputs you can change; blue headers are fixed; every figure is an ESTIMATE unless labelled VERIFIED (see FACTS_BASE).

Sheet README
A1: VYTALIX — 36-month financial model (Jan 2027 – Dec 2029)
A3: Status: SCENARIO MODEL v1.1, built 7 September 2026 and revised 8 September 2026 by finance/build_model.py. GBP. UK-domiciled entity (to be incorporated — TO VALIDATE).
A4: No figure in this workbook is an actual. Vytalix has no revenue, customers, contracts, grants or product in production (FACTS_BASE.md). Every number is a scenario built from the stated assumptions.
A6: HOW TO USE
A7: 1. Assumptions!C4 selects the scenario (1 Conservative, 2 Base, 3 High-growth). Column F ('ACTIVE') = INDEX(C:E, selector) and every formula sheet reads column F.
A8: 2. Blue/yellow cells in Assumptions are inputs. Year-dependent inputs (Y1/Y2/Y3) are read with CHOOSE(year index, Y1, Y2, Y3).
A9: 3. Timeline sheets run left to right: Revenue build → Cost of sales → Headcount → Opex → P&L → Cash flow → Funding requirement → Dashboard. Months are in columns C:AL; annual totals in AN:AQ.
A10: 4. Sensitivity and Static summary are values computed in Python with identical logic; they do not react to C4. Re-run the script after editing assumptions.
A11: 5. Assumptions!ml_delay adds months to the MaternaLink licence go-live for slippage tests.
A13: SHEETS
A14: Assumptions — three scenario columns, selector, derived payroll on-costs. | Revenue build — advisory days × rate × utilisation, retainers, consulting projects × value, e-learning learners × ARPU + corporate licences, MaternaLink pilots × value then per-woman licences from go-live.
A15: Cost of sales — direct costs and gross margin. | Opex — founder salary, hires by start month, contractors, technology, marketing, legal, compliance, insurance, software, travel, operations, accountancy; employer NI 15% above £5,000 and pension 3% of qualifying earnings (2026/27 — see notes in Assumptions).
... A37: EIS from 6 April 2026: £10m per 12 months (£20m knowledge-intensive), £24m lifetime (£40m KIC), gross assets £30m/£35m, investor £1m (£2m KIC): https://www.farrer.co.uk/news-and-insights/using-eis-and-seis-to-attract-investment-the-benefits-and-some-traps-to-avoid/ ; https://ct.me/content-hub/articles/eis-changes-from-april-2026-higher-investment-limits-for-innovative-companies/

Sheet Assumptions
A1: VYTALIX — Assumptions (all values are scenario inputs; none are actuals)
A2: Labels: KNOWN (cited) · ESTIMATE · ASSUMPTION · PROPOSED · TO VALIDATE. Blue cells are inputs. Column F = active scenario via INDEX.
A4: SCENARIO SELECTOR (1 = Conservative, 2 = Base, 3 = High-growth) | C4: 2 | D4: =INDEX({"Conservative","Base","High-growth"},1,$C$4)
A5: Change C4 and the whole workbook (Revenue → Cash flow → Dashboard) re-points. Sensitivity and Static summary are Python-computed values and do not change.
A7: Key | B7: Assumption | C7: Conservative | D7: Base | E7: High-growth | F7: ACTIVE | G7: Unit | H7: Label | I7: Note / source
A8: General
A9: opening_cash | B9: Opening cash (founder capital + director's loan, month 1) | C9: 25000 | D9: 35000 | E9: 50000 | F9: =INDEX($C9:$E9,1,$C$4) | G9: GBP | H9: ASSUMPTION | I9: Founder's own contribution incl. a director's loan that bridges month-1 set-up costs until the pre-seed lands; TO VALIDATE with founder. (Revised 8 Sept 2026 from £10k/£20k/£30k, which left cash negative in months 2–5 of every scenario.)
A10: collection_lag | B10: Collection lag — services & MaternaLink invoices | C10: 1 | D10: 1 | E10: 1 | F10: =INDEX($C10:$E10,1,$C$4) | G10: months | H10: ASSUMPTION | I10: E-learning collected same month (prepaid).
A11: avail_days | B11: Founder available working days per month | C11: 17.33 | D11: 17.33 | E11: 17.33 | F11: =INDEX($C11:$E11,1,$C$4) | G11: days | H11: ASSUMPTION | I11: 208 days/year ÷ 12 (4 days/week on Vytalix, per 01_BUSINESS_MODEL).
A12: ramp_months | B12: Sales ramp-up (months to full run-rate) | C12: 4 | D12: 3 | E12: 2 | F12: =INDEX($C12:$E12,1,$C$4) | G12: months | H12: ASSUMPTION | I12: Ramp factor = MIN(1,(month-1)/ramp). Month 1 = 0 revenue (incorporation, outreach).
A13: Advisory (founder-led days and retainers)
A14: day_rate | B14: Founder day rate | C14: 1200 | D14: 1500 | E14: 1800 | F14: =INDEX($C14:$E14,1,$C$4) | G14: GBP/day | H14: ESTIMATE | I14: Range £1,200–£1,800 per 01_BUSINESS_MODEL §4.1.
A15: utilisation | B15: Founder billable utilisation (all client work) | C15: 0.3 | D15: 0.42 | E15: 0.55 | F15: =INDEX($C15:$E15,1,$C$4) | G15: % | H15: ESTIMATE | I15: Share of available days billed (advisory days + retainers + consulting delivery).
A16: ret_start | B16: Retainers — first retainer month | C16: 3 | D16: 2 | E16: 2 | F16: =INDEX($C16:$E16,1,$C$4) | G16: month | H16: ASSUMPTION
A17: ret_y1 | B17: Retainers active — Y1 (average) | C17: 0.5 | D17: 1 | E17: 2 | F17: =INDEX($C17:$E17,1,$C$4) | G17: count | H17: ESTIMATE | I17: Fractional = part-year.
A18: ret_y2 | B18: Retainers active — Y2 (average) | C18: 1 | D18: 2 | E18: 3 | F18: =INDEX($C18:$E18,1,$C$4) | G18: count | H18: ESTIMATE
A19: ret_y3 | B19: Retainers active — Y3 (average) | C19: 1 | D19: 2 | E19: 3 | F19: =INDEX($C19:$E19,1,$C$4) | G19: count | H19: ESTIMATE
A20: ret_fee | B20: Retainer fee per month | C20: 3500 | D20: 4000 | E20: 5000 | F20: =INDEX($C20:$E20,1,$C$4) | G20: GBP/month | H20: ESTIMATE | I20: £2,500–£6,000 per 01_BUSINESS_MODEL #2.
A21: ret_days | B21: Founder days consumed per retainer per month | C21: 2.5 | D21: 2.5 | E21: 2.5 | F21: =INDEX($C21:$E21,1,$C$4) | G21: days | H21: ASSUMPTION
A22: adv_cost_day | B22: Direct cost per founder billable day (travel, tools) | C22: 50 | D22: 50 | E22: 50 | F22: =INDEX($C22:$E22,1,$C$4) | G22: GBP/day | H22: ESTIMATE
A23: cons_days | B23: Senior consultant billable days per month (once hired) | C23: 0 | D23: 10 | E23: 10 | F23: =INDEX($C23:$E23,1,$C$4) | G23: days | H23: ASSUMPTION | I23: Hire start month in Headcount block; 0 if never hired.
A24: cons_rate | B24: Senior consultant billed day rate | C24: 900 | D24: 900 | E24: 1000 | F24: =INDEX($C24:$E24,1,$C$4) | G24: GBP/day | H24: ESTIMATE | I24: Associate-level rate £700–£1,000 per 01_BUSINESS_MODEL.
A25: Consulting (packaged projects)
A26: proj_y1 | B26: Projects won — Y1 | C26: 2 | D26: 5 | E26: 8 | F26: =INDEX($C26:$E26,1,$C$4) | G26: count | H26: ESTIMATE | I26: Spread evenly across the year after ramp.
A27: proj_y2 | B27: Projects won — Y2 | C27: 4 | D27: 8 | E27: 14 | F27: =INDEX($C27:$E27,1,$C$4) | G27: count | H27: ESTIMATE
A28: proj_y3 | B28: Projects won — Y3 | C28: 5 | D28: 10 | E28: 18 | F28: =INDEX($C28:$E28,1,$C$4) | G28: count | H28: ESTIMATE
A29: proj_value | B29: Average project value | C29: 15000 | D29: 20000 | E29: 30000 | F29: =INDEX($C29:$E29,1,$C$4) | G29: GBP | H29: ESTIMATE | I29: Range £15k–£60k; catalogue prices £9.5k–£28k in 01_BUSINESS_MODEL §5.
A30: fdays_proj | B30: Founder days per project | C30: 8 | D30: 7 | E30: 5 | F30: =INDEX($C30:$E30,1,$C$4) | G30: days | H30: ASSUMPTION | I30: Lower in High-growth because associates deliver more (see delivery cost %).
A31: proj_cost_pct | B31: Consulting delivery cost (associates, expenses) % of value | C31: 0.3 | D31: 0.35 | E31: 0.45 | F31: =INDEX($C31:$E31,1,$C$4) | G31: % | H31: ESTIMATE | I31: Cost of sales. Rises with associate share.
A32: E-learning
A33: el_launch | B33: E-learning launch month | C33: 12 | D33: 9 | E33: 7 | F33: =INDEX($C33:$E33,1,$C$4) | G33: month | H33: ASSUMPTION | I33: Two founder-authored courses first (01_BUSINESS_MODEL §6).
A34: el_init | B34: New learners per month at launch | C34: 8 | D34: 15 | E34: 30 | F34: =INDEX($C34:$E34,1,$C$4) | G34: learners | H34: ESTIMATE
A35: el_growth | B35: Monthly growth in new learners | C35: 0.03 | D35: 0.05 | E35: 0.07 | F35: =INDEX($C35:$E35,1,$C$4) | G35: % | H35: ESTIMATE | I35: Compound, from launch.
A36: el_arpu | B36: Average revenue per learner (ARPU) | C36: 150 | D36: 200 | E36: 300 | F36: =INDEX($C36:$E36,1,$C$4) | G36: GBP | H36: ESTIMATE | I36: Range £150–£400; course prices £49–£299 UK, regional pricing lower.
A37: corp_y1 | B37: Corporate licences active — Y1 | C37: 0 | D37: 0 | E37: 1 | F37: =INDEX($C37:$E37,1,$C$4) | G37: count | H37: ESTIMATE
A38: corp_y2 | B38: Corporate licences active — Y2 | C38: 1 | D38: 3 | E38: 6 | F38: =INDEX($C38:$E38,1,$C$4) | G38: count | H38: ESTIMATE
A39: corp_y3 | B39: Corporate licences active — Y3 | C39: 2 | D39: 6 | E39: 12 | F39: =INDEX($C39:$E39,1,$C$4) | G39: count | H39: ESTIMATE
A40: corp_value | B40: Corporate licence value per year | C40: 2500 | D40: 5000 | E40: 9000 | F40: =INDEX($C40:$E40,1,$C$4) | G40: GBP/year | H40: ESTIMATE | I40: £2,500 (10 seats) – £25,000 (250 seats) ladder.
A41: el_cos_pct | B41: E-learning platform + payment fees % of revenue | C41: 0.15 | D41: 0.15 | E41: 0.15 | F41: =INDEX($C41:$E41,1,$C$4) | G41: % | H41: ESTIMATE
A42: el_content | B42: E-learning content build (one-off, launch month) | C42: 8000 | D42: 12000 | E42: 20000 | F42: =INDEX($C42:$E42,1,$C$4) | G42: GBP | H42: ESTIMATE | I42: £8k–£15k per course; two courses at launch (High builds more).
...

Sheet Revenue build
A1: Revenue build — Advisory, Consulting, E-learning, MaternaLink (in development)
A2: ="Scenario: "&Assumptions!$D$4&" — all figures GBP, scenario values, not actuals"
A3: Month # | C3: 1 | D3: 2 | E3: 3 | F3: 4 | G3: 5 | H3: 6 | I3: 7 | J3: 8 | K3: 9 | L3: 10 | M3: 11 | N3: 12 | O3: 13 | P3: 14 | Q3: 15 | R3: 16 | S3: 17 | T3: 18 | U3: 19 | V3: 20 | W3: 21 | X3: 22 | Y3: 23 | Z3: 24 | AA3: 25 | AB3: 26 | AC3: 27 | AD3: 28 | AE3: 29 | AF3: 30 | AG3: 31 | AH3: 32 | AI3: 33 | AJ3: 34 | AK3: 35 | AL3: 36
A4: Month | C4: 46388 | D4: 46419 | E4: 46447 | F4: 46478 | G4: 46508 | H4: 46539 | I4: 46569 | J4: 46600 | K4: 46631 | L4: 46661 | M4: 46692 | N4: 46722 | O4: 46753 | P4: 46784 | Q4: 46813 | R4: 46844 | S4: 46874 | T4: 46905 | U4: 46935 | V4: 46966 | W4: 46997 | X4: 47027 | Y4: 47058 | Z4: 47088 | AA4: 47119 | AB4: 47150 | AC4: 47178 | AD4: 47209 | AE4: 47239 | AF4: 47270 | AG4: 47300 | AH4: 47331 | AI4: 47362 | AJ4: 47392 | AK4: 47423 | AL4: 47453 | AN4: FY2027 | AO4: FY2028 | AP4: FY2029 | AQ4: 3-year total
A5: Year | C5: 2027 | D5: 2027 | E5: 2027 | F5: 2027 | G5: 2027 | H5: 2027 | I5: 2027 | J5: 2027 | K5: 2027 | L5: 2027 | M5: 2027 | N5: 2027 | O5: 2028 | P5: 2028 | Q5: 2028 | R5: 2028 | S5: 2028 | T5: 2028 | U5: 2028 | V5: 2028 | W5: 2028 | X5: 2028 | Y5: 2028 | Z5: 2028 | AA5: 2029 | AB5: 2029 | AC5: 2029 | AD5: 2029 | AE5: 2029 | AF5: 2029 | AG5: 2029 | AH5: 2029 | AI5: 2029 | AJ5: 2029 | AK5: 2029 | AL5: 2029 | AN5: 2027 | AO5: 2028 | AP5: 2029
A6: Year index | C6: =C5-2026 | D6: =D5-2026 | E6: =E5-2026 | F6: =F5-2026 | G6: =G5-2026 | H6: =H5-2026 | I6: =I5-2026 | J6: =J5-2026 | ... AL6: =AL5-2026
A7: Sales ramp factor | C7: =MIN(1,MAX(0,(C3-1)/Assumptions!$F$12)) | D7: =MIN(1,MAX(0,(D3-1)/Assumptions!$F$12)) | E7: =MIN(1,MAX(0,(E3-1)/Assumptions!$F$12)) | F7: =MIN(1,MAX(0,(F3-1)/Assumptions!$F$12)) | G7: =MIN(1,MAX(0,(G3-1)/Assumptions!$F$12)) | H7: =MIN(1,MAX(0,(H3-1)/Assumptions!$F$12)) | I7: =MIN(1,MAX(0,(I3-1)/Assumptions!$F$12)) | J7: =MIN(1,MAX(0,(J3-1)/Assumptions!$F$12)) | ... AL7: =MIN(1,MAX(0,(AL3-1)/Assumptions!$F$12)) | AN7: =AVERAGEIF($C$5:$AL$5,AN$5,C7:AL7) | AO7: =AVERAGEIF($C$5:$AL$5,AO$5,C7:AL7) | AP7: =AVERAGEIF($C$5:$AL$5,AP$5,C7:AL7) | AQ7: =AVERAGE(C7:AL7)
A8: ADVISORY
A9: Founder available days | B9: days | C9: =Assumptions!$F$11 | D9: =Assumptions!$F$11 | E9: =Assumptions!$F$11 | F9: =Assumptions!$F$11 | G9: =Assumptions!$F$11 | H9: =Assumptions!$F$11 | I9: =Assumptions!$F$11 | J9: =Assumptions!$F$11 | ... AL9: =Assumptions!$F$11 | AN9: =SUMIF($C$5:$AL$5,AN$5,C9:AL9) | AO9: =SUMIF($C$5:$AL$5,AO$5,C9:AL9) | AP9: =SUMIF($C$5:$AL$5,AP$5,C9:AL9) | AQ9: =SUM(C9:AL9)
A10: Founder billable utilisation | C10: =Assumptions!$F$15 | D10: =Assumptions!$F$15 | E10: =Assumptions!$F$15 | F10: =Assumptions!$F$15 | G10: =Assumptions!$F$15 | H10: =Assumptions!$F$15 | I10: =Assumptions!$F$15 | J10: =Assumptions!$F$15 | ... AL10: =Assumptions!$F$15 | AN10: =AVERAGEIF($C$5:$AL$5,AN$5,C10:AL10) | AO10: =AVERAGEIF($C$5:$AL$5,AO$5,C10:AL10) | AP10: =AVERAGEIF($C$5:$AL$5,AP$5,C10:AL10) | AQ10: =AVERAGE(C10:AL10)
A11: Founder billable days (utilisation × ramp) | B11: days | C11: ='Revenue build'!C9*'Revenue build'!C10*'Revenue build'!C7 | D11: ='Revenue build'!D9*'Revenue build'!D10*'Revenue build'!D7 | E11: ='Revenue build'!E9*'Revenue build'!E10*'Revenue build'!E7 | F11: ='Revenue build'!F9*'Revenue build'!F10*'Revenue build'!F7 | G11: ='Revenue build'!G9*'Revenue build'!G10*'Revenue build'!G7 | H11: ='Revenue build'!H9*'Revenue build'!H10*'Revenue build'!H7 | I11: ='Revenue build'!I9*'Revenue build'!I10*'Revenue build'!I7 | J11: ='Revenue build'!J9*'Revenue build'!J10*'Revenue build'!J7 | ... AL11: ='Revenue build'!AL9*'Revenue build'!AL10*'Revenue build'!AL7 | AN11: =SUMIF($C$5:$AL$5,AN$5,C11:AL11) | AO11: =SUMIF($C$5:$AL$5,AO$5,C11:AL11) | AP11: =SUMIF($C$5:$AL$5,AP$5,C11:AL11) | AQ11: =SUM(C11:AL11)
A12: Retainers active | B12: count | C12: =IF(C3>=Assumptions!$F$16,CHOOSE(C6,Assumptions!$F$17,Assumptions!$F$18,Assumptions!$F$19),0) | D12: =IF(D3>=Assumptions!$F$16,CHOOSE(D6,Assumptions!$F$17,Assumptions!$F$18,Assumptions!$F$19),0) | E12: =IF(E3>=Assumptions!$F$16,CHOOSE(E6,Assumptions!$F$17,Assumptions!$F$18,Assumptions!$F$19),0) | F12: =IF(F3>=Assumptions!$F$16,CHOOSE(F6,Assumptions!$F$17,Assumptions!$F$18,Assumptions!$F$19),0) | G12: =IF(G3>=Assumptions!$F$16,CHOOSE(G6,Assumptions!$F$17,Assumptions!$F$18,Assumptions!$F$19),0) | H12: =IF(H3>=Assumptions!$F$16,CHOOSE(H6,Assumptions!$F$17,Assumptions!$F$18,Assumptions!$F$19),0) | I12: =IF(I3>=Assumptions!$F$16,CHOOSE(I6,Assumptions!$F$17,Assumptions!$F$18,Assumptions!$F$19),0) | J12: =IF(J3>=Assumptions!$F$16,CHOOSE(J6,Assumptions!$F$17,Assumptions!$F$18,Assumptions!$F$19),0) | ... AL12: =IF(AL3>=Assumptions!$F$16,CHOOSE(AL6,Assumptions!$F$17,Assumptions!$F$18,Assumptions!$F$19),0) | AN12: =AVERAGEIF($C$5:$AL$5,AN$5,C12:AL12) | AO12: =AVERAGEIF($C$5:$AL$5,AO$5,C12:AL12) | AP12: =AVERAGEIF($C$5:$AL$5,AP$5,C12:AL12) | AQ12: =AVERAGE(C12:AL12)
A13: Founder days consumed by retainers | B13: days | C13: ='Revenue build'!C12*Assumptions!$F$21 | D13: ='Revenue build'!D12*Assumptions!$F$21 | E13: ='Revenue build'!E12*Assumptions!$F$21 | F13: ='Revenue build'!F12*Assumptions!$F$21 | G13: ='Revenue build'!G12*Assumptions!$F$21 | H13: ='Revenue build'!H12*Assumptions!$F$21 | I13: ='Revenue build'!I12*Assumptions!$F$21 | J13: ='Revenue build'!J12*Assumptions!$F$21 | ... AL13: ='Revenue build'!AL12*Assumptions!$F$21 | AN13: =SUMIF($C$5:$AL$5,AN$5,C13:AL13) | AO13: =SUMIF($C$5:$AL$5,AO$5,C13:AL13) | AP13: =SUMIF($C$5:$AL$5,AP$5,C13:AL13) | AQ13: =SUM(C13:AL13)
A14: Consulting projects (per month, smoothed) | B14: count | C14: =CHOOSE(C6,Assumptions!$F$26,Assumptions!$F$27,Assumptions!$F$28)/12*'Revenue build'!C7 | D14: =CHOOSE(D6,Assumptions!$F$26,Assumptions!$F$27,Assumptions!$F$28)/12*'Revenue build'!D7 | E14: =CHOOSE(E6,Assumptions!$F$26,Assumptions!$F$27,Assumptions!$F$28)/12*'Revenue build'!E7 | F14: =CHOOSE(F6,Assumptions!$F$26,Assumptions!$F$27,Assumptions!$F$28)/12*'Revenue build'!F7 | G14: =CHOOSE(G6,Assumptions!$F$26,Assumptions!$F$27,Assumptions!$F$28)/12*'Revenue build'!G7 | H14: =CHOOSE(H6,Assumptions!$F$26,Assumptions!$F$27,Assumptions!$F$28)/12*'Revenue build'!H7 | I14: =CHOOSE(I6,Assumptions!$F$26,Assumptions!$F$27,Assumptions!$F$28)/12*'Revenue build'!I7 | J14: =CHOOSE(J6,Assumptions!$F$26,Assumptions!$F$27,Assumptions!$F$28)/12*'Revenue build'!J7 | ... AL14: =CHOOSE(AL6,Assumptions!$F$26,Assumptions!$F$27,Assumptions!$F$28)/12*'Revenue build'!AL7 | AN14: =SUMIF($C$5:$AL$5,AN$5,C14:AL14) | AO14: =SUMIF($C$5:$AL$5,AO$5,C14:AL14) | AP14: =SUMIF($C$5:$AL$5,AP$5,C14:AL14) | AQ14: =SUM(C14:AL14)
A15: Founder days consumed by consulting delivery | B15: days | C15: ='Revenue build'!C14*Assumptions!$F$30 | D15: ='Revenue build'!D14*Assumptions!$F$30 | E15: ='Revenue build'!E14*Assumptions!$F$30 | F15: ='Revenue build'!F14*Assumptions!$F$30 | G15: ='Revenue build'!G14*Assumptions!$F$30 | H15: ='Revenue build'!H14*Assumptions!$F$30 | I15: ='Revenue build'!I14*Assumptions!$F$30 | J15: ='Revenue build'!J14*Assumptions!$F$30 | ... AL15: ='Revenue build'!AL14*Assumptions!$F$30 | AN15: =SUMIF($C$5:$AL$5,AN$5,C15:AL15) | AO15: =SUMIF($C$5:$AL$5,AO$5,C15:AL15) | AP15: =SUMIF($C$5:$AL$5,AP$5,C15:AL15) | AQ15: =SUM(C15:AL15)
A16: Advisory day-rate days sold (residual capacity) | B16: days | C16: =MAX(0,'Revenue build'!C11-'Revenue build'!C13-'Revenue build'!C15) | D16: =MAX(0,'Revenue build'!D11-'Revenue build'!D13-'Revenue build'!D15) | E16: =MAX(0,'Revenue build'!E11-'Revenue build'!E13-'Revenue build'!E15) | F16: =MAX(0,'Revenue build'!F11-'Revenue build'!F13-'Revenue build'!F15) | G16: =MAX(0,'Revenue build'!G11-'Revenue build'!G13-'Revenue build'!G15) | H16: =MAX(0,'Revenue build'!H11-'Revenue build'!H13-'Revenue build'!H15) | I16: =MAX(0,'Revenue build'!I11-'Revenue build'!I13-'Revenue build'!I15) | J16: =MAX(0,'Revenue build'!J11-'Revenue build'!J13-'Revenue build'!J15) | ... AL16: =MAX(0,'Revenue build'!AL11-'Revenue build'!AL13-'Revenue build'!AL15) | AN16: =SUMIF($C$5:$AL$5,AN$5,C16:AL16) | AO16: =SUMIF($C$5:$AL$5,AO$5,C16:AL16) | AP16: =SUMIF($C$5:$AL$5,AP$5,C16:AL16) | AQ16: =SUM(C16:AL16)
A17: Founder capacity used by retainers + projects (>100% = associate-dependent) | C17: =IF('Revenue build'!C11>0,('Revenue build'!C13+'Revenue build'!C15)/'Revenue build'!C11,0) | D17: =IF('Revenue build'!D11>0,('Revenue build'!D13+'Revenue build'!D15)/'Revenue build'!D11,0) | E17: =IF('Revenue build'!E11>0,('Revenue build'!E13+'Revenue build'!E15)/'Revenue build'!E11,0) | F17: =IF('Revenue build'!F11>0,('Revenue build'!F13+'Revenue build'!F15)/'Revenue build'!F11,0) | G17: =IF('Revenue build'!G11>0,('Revenue build'!G13+'Revenue build'!G15)/'Revenue build'!G11,0) | H17: =IF('Revenue build'!H11>0,('Revenue build'!H13+'Revenue build'!H15)/'Revenue build'!H11,0) | I17: =IF('Revenue build'!I11>0,('Revenue build'!I13+'Revenue build'!I15)/'Revenue build'!I11,0) | J17: =IF('Revenue build'!J11>0,('Revenue build'!J13+'Revenue build'!J15)/'Revenue build'!J11,0) | ... AL17: =IF('Revenue build'!AL11>0,('Revenue build'!AL13+'Revenue build'!AL15)/'Revenue build'!AL11,0) | AN17: =AVERAGEIF($C$5:$AL$5,AN$5,C17:AL17) | AO17: =AVERAGEIF($C$5:$AL$5,AO$5,C17:AL17) | AP17: =AVERAGEIF($C$5:$AL$5,AP$5,C17:AL17) | AQ17: =AVERAGE(C17:AL17)
A18: Founder day rate | B18: GBP/day | C18: =Assumptions!$F$14 | D18: =Assumptions!$F$14 | E18: =Assumptions!$F$14 | F18: =Assumptions!$F$14 | G18: =Assumptions!$F$14 | H18: =Assumptions!$F$14 | I18: =Assumptions!$F$14 | J18: =Assumptions!$F$14 | ... AL18: =Assumptions!$F$14 | AN18: =AVERAGEIF($C$5:$AL$5,AN$5,C18:AL18) | AO18: =AVERAGEIF($C$5:$AL$5,AO$5,C18:AL18) | AP18: =AVERAGEIF($C$5:$AL$5,AP$5,C18:AL18) | AQ18: =AVERAGE(C18:AL18)
A19: Advisory day-rate revenue | C19: ='Revenue build'!C16*'Revenue build'!C18 | D19: ='Revenue build'!D16*'Revenue build'!D18 | E19: ='Revenue build'!E16*'Revenue build'!E18 | F19: ='Revenue build'!F16*'Revenue build'!F18 | G19: ='Revenue build'!G16*'Revenue build'!G18 | H19: ='Revenue build'!H16*'Revenue build'!H18 | I19: ='Revenue build'!I16*'Revenue build'!I18 | J19: ='Revenue build'!J16*'Revenue build'!J18 | ... AL19: ='Revenue build'!AL16*'Revenue build'!AL18 | AN19: =SUMIF($C$5:$AL$5,AN$5,C19:AL19) | AO19: =SUMIF($C$5:$AL$5,AO$5,C19:AL19) | AP19: =SUMIF($C$5:$AL$5,AP$5,C19:AL19) | AQ19: =SUM(C19:AL19)
A20: Retainer revenue | C20: ='Revenue build'!C12*Assumptions!$F$20 | D20: ='Revenue build'!D12*Assumptions!$F$20 | E20: ='Revenue build'!E12*Assumptions!$F$20 | F20: ='Revenue build'!F12*Assumptions!$F$20 | G20: ='Revenue build'!G12*Assumptions!$F$20 | H20: ='Revenue build'!H12*Assumptions!$F$20 | I20: ='Revenue build'!I12*Assumptions!$F$20 | J20: ='Revenue build'!J12*Assumptions!$F$20 | ... AL20: ='Revenue build'!AL12*Assumptions!$F$20 | AN20: =SUMIF($C$5:$AL$5,AN$5,C20:AL20) | AO20: =SUMIF($C$5:$AL$5,AO$5,C20:AL20) | AP20: =SUMIF($C$5:$AL$5,AP$5,C20:AL20) | AQ20: =SUM(C20:AL20)
A21: Senior consultant billable days | B21: days | C21: ='Headcount'!C17*Assumptions!$F$23 | D21: ='Headcount'!D17*Assumptions!$F$23 | E21: ='Headcount'!E17*Assumptions!$F$23 | F21: ='Headcount'!F17*Assumptions!$F$23 | G21: ='Headcount'!G17*Assumptions!$F$23 | H21: ='Headcount'!H17*Assumptions!$F$23 | I21: ='Headcount'!I17*Assumptions!$F$23 | J21: ='Headcount'!J17*Assumptions!$F$23 | ... AL21: ='Headcount'!AL17*Assumptions!$F$23 | AN21: =SUMIF($C$5:$AL$5,AN$5,C21:AL21) | AO21: =SUMIF($C$5:$AL$5,AO$5,C21:AL21) | AP21: =SUMIF($C$5:$AL$5,AP$5,C21:AL21) | AQ21: =SUM(C21:AL21)
A22: Senior consultant revenue | C22: ='Revenue build'!C21*Assumptions!$F$24 | D22: ='Revenue build'!D21*Assumptions!$F$24 | E22: ='Revenue build'!E21*Assumptions!$F$24 | F22: ='Revenue build'!F21*Assumptions!$F$24 | G22: ='Revenue build'!G21*Assumptions!$F$24 | H22: ='Revenue build'!H21*Assumptions!$F$24 | I22: ='Revenue build'!I21*Assumptions!$F$24 | J22: ='Revenue build'!J21*Assumptions!$F$24 | ... AL22: ='Revenue build'!AL21*Assumptions!$F$24 | AN22: =SUMIF($C$5:$AL$5,AN$5,C22:AL22) | AO22: =SUMIF($C$5:$AL$5,AO$5,C22:AL22) | AP22: =SUMIF($C$5:$AL$5,AP$5,C22:AL22) | AQ22: =SUM(C22:AL22)
A23: ADVISORY REVENUE | C23: ='Revenue build'!C19+'Revenue build'!C20+'Revenue build'!C22 | D23: ='Revenue build'!D19+'Revenue build'!D20+'Revenue build'!D22 | E23: ='Revenue build'!E19+'Revenue build'!E20+'Revenue build'!E22 | F23: ='Revenue build'!F19+'Revenue build'!F20+'Revenue build'!F22 | G23: ='Revenue build'!G19+'Revenue build'!G20+'Revenue build'!G22 | H23: ='Revenue build'!H19+'Revenue build'!H20+'Revenue build'!H22 | I23: ='Revenue build'!I19+'Revenue build'!I20+'Revenue build'!I22 | J23: ='Revenue build'!J19+'Revenue build'!J20+'Revenue build'!J22 | ... AL23: ='Revenue build'!AL19+'Revenue build'!AL20+'Revenue build'!AL22 | AN23: =SUMIF($C$5:$AL$5,AN$5,C23:AL23) | AO23: =SUMIF($C$5:$AL$5,AO$5,C23:AL23) | AP23: =SUMIF($C$5:$AL$5,AP$5,C23:AL23) | AQ23: =SUM(C23:AL23)
A25: CONSULTING
A26: Average project value | B26: GBP | C26: =Assumptions!$F$29 | D26: =Assumptions!$F$29 | E26: =Assumptions!$F$29 | F26: =Assumptions!$F$29 | G26: =Assumptions!$F$29 | H26: =Assumptions!$F$29 | I26: =Assumptions!$F$29 | J26: =Assumptions!$F$29 | ... AL26: =Assumptions!$F$29 | AN26: =AVERAGEIF($C$5:$AL$5,AN$5,C26:AL26) | AO26: =AVERAGEIF($C$5:$AL$5,AO$5,C26:AL26) | AP26: =AVERAGEIF($C$5:$AL$5,AP$5,C26:AL26) | AQ26: =AVERAGE(C26:AL26)
A27: CONSULTING REVENUE (projects × value) | C27: ='Revenue build'!C14*'Revenue build'!C26 | D27: ='Revenue build'!D14*'Revenue build'!D26 | E27: ='Revenue build'!E14*'Revenue build'!E26 | F27: ='Revenue build'!F14*'Revenue build'!F26 | G27: ='Revenue build'!G14*'Revenue build'!G26 | H27: ='Revenue build'!H14*'Revenue build'!H26 | I27: ='Revenue build'!I14*'Revenue build'!I26 | J27: ='Revenue build'!J14*'Revenue build'!J26 | ... AL27: ='Revenue build'!AL14*'Revenue build'!AL26 | AN27: =SUMIF($C$5:$AL$5,AN$5,C27:AL27) | AO27: =SUMIF($C$5:$AL$5,AO$5,C27:AL27) | AP27: =SUMIF($C$5:$AL$5,AP$5,C27:AL27) | AQ27: =SUM(C27:AL27)
A29: E-LEARNING
A30: Launched (1/0) | C30: =IF(C3>=Assumptions!$F$33,1,0) | D30: =IF(D3>=Assumptions!$F$33,1,0) | E30: =IF(E3>=Assumptions!$F$33,1,0) | F30: =IF(F3>=Assumptions!$F$33,1,0) | G30: =IF(G3>=Assumptions!$F$33,1,0) | H30: =IF(H3>=Assumptions!$F$33,1,0) | I30: =IF(I3>=Assumptions!$F$33,1,0) | J30: =IF(J3>=Assumptions!$F$33,1,0) | ... AL30: =IF(AL3>=Assumptions!$F$33,1,0) | AN30: =INDEX(C30:AL30,1,12) | AO30: =INDEX(C30:AL30,1,24) | AP30: =INDEX(C30:AL30,1,36) | AQ30: =INDEX(C30:AL30,1,36)
A31: New learners per month | B31: learners | C31: =IF('Revenue build'!C30=1,Assumptions!$F$34*(1+Assumptions!$F$35)^(C3-Assumptions!$F$33),0) | D31: =IF('Revenue build'!D30=1,Assumptions!$F$34*(1+Assumptions!$F$35)^(D3-Assumptions!$F$33),0) | E31: =IF('Revenue build'!E30=1,Assumptions!$F$34*(1+Assumptions!$F$35)^(E3-Assumptions!$F$33),0) | F31: =IF('Revenue build'!F30=1,Assumptions!$F$34*(1+Assumptions!$F$35)^(F3-Assumptions!$F$33),0) | G31: =IF('Revenue build'!G30=1,Assumptions!$F$34*(1+Assumptions!$F$35)^(G3-Assumptions!$F$33),0) | H31: =IF('Revenue build'!H30=1,Assumptions!$F$34*(1+Assumptions!$F$35)^(H3-Assumptions!$F$33),0) | I31: =IF('Revenue build'!I30=1,Assumptions!$F$34*(1+Assumptions!$F$35)^(I3-Assumptions!$F$33),0) | J31: =IF('Revenue build'!J30=1,Assumptions!$F$34*(1+Assumptions!$F$35)^(J3-Assumptions!$F$33),0) | ... AL31: =IF('Revenue build'!AL30=1,Assumptions!$F$34*(1+Assumptions!$F$35)^(AL3-Assumptions!$F$33),0) | AN31: =SUMIF($C$5:$AL$5,AN$5,C31:AL31) | AO31: =SUMIF($C$5:$AL$5,AO$5,C31:AL31) | AP31: =SUMIF($C$5:$AL$5,AP$5,C31:AL31) | AQ31: =SUM(C31:AL31)
A32: ARPU | B32: GBP | C32: =Assumptions!$F$36 | D32: =Assumptions!$F$36 | E32: =Assumptions!$F$36 | F32: =Assumptions!$F$36 | G32: =Assumptions!$F$36 | H32: =Assumptions!$F$36 | I32: =Assumptions!$F$36 | J32: =Assumptions!$F$36 | ... AL32: =Assumptions!$F$36 | AN32: =AVERAGEIF($C$5:$AL$5,AN$5,C32:AL32) | AO32: =AVERAGEIF($C$5:$AL$5,AO$5,C32:AL32) | AP32: =AVERAGEIF($C$5:$AL$5,AP$5,C32:AL32) | AQ32: =AVERAGE(C32:AL32)
A33: Course revenue (learners × ARPU) | C33: ='Revenue build'!C31*'Revenue build'!C32 | D33: ='Revenue build'!D31*'Revenue build'!D32 | E33: ='Revenue build'!E31*'Revenue build'!E32 | F33: ='Revenue build'!F31*'Revenue build'!F32 | G33: ='Revenue build'!G31*'Revenue build'!G32 | H33: ='Revenue build'!H31*'Revenue build'!H32 | I33: ='Revenue build'!I31*'Revenue build'!I32 | J33: ='Revenue build'!J31*'Revenue build'!J32 | ... AL33: ='Revenue build'!AL31*'Revenue build'!AL32 | AN33: =SUMIF($C$5:$AL$5,AN$5,C33:AL33) | AO33: =SUMIF($C$5:$AL$5,AO$5,C33:AL33) | AP33: =SUMIF($C$5:$AL$5,AP$5,C33:AL33) | AQ33: =SUM(C33:AL33)
A34: Corporate licences active | B34: count | C34: ='Revenue build'!C30*CHOOSE(C6,Assumptions!$F$37,Assumptions!$F$38,Assumptions!$F$39) | D34: ='Revenue build'!D30*CHOOSE(D6,Assumptions!$F$37,Assumptions!$F$38,Assumptions!$F$39) | E34: ='Revenue build'!E30*CHOOSE(E6,Assumptions!$F$37,Assumptions!$F$38,Assumptions!$F$39) | F34: ='Revenue build'!F30*CHOOSE(F6,Assumptions!$F$37,Assumptions!$F$38,Assumptions!$F$39) | G34: ='Revenue build'!G30*CHOOSE(G6,Assumptions!$F$37,Assumptions!$F$38,Assumptions!$F$39) | H34: ='Revenue build'!H30*CHOOSE(H6,Assumptions!$F$37,Assumptions!$F$38,Assumptions!$F$39) | I34: ='Revenue build'!I30*CHOOSE(I6,Assumptions!$F$37,Assumptions!$F$38,Assumptions!$F$39) | J34: ='Revenue build'!J30*CHOOSE(J6,Assumptions!$F$37,Assumptions!$F$38,Assumptions!$F$39) | ... AL34: ='Revenue build'!AL30*CHOOSE(AL6,Assumptions!$F$37,Assumptions!$F$38,Assumptions!$F$39) | AN34: =AVERAGEIF($C$5:$AL$5,AN$5,C34:AL34) | AO34: =AVERAGEIF($C$5:$AL$5,AO$5,C34:AL34) | AP34: =AVERAGEIF($C$5:$AL$5,AP$5,C34:AL34) | AQ34: =AVERAGE(C34:AL34)
A35: Corporate licence revenue | C35: ='Revenue build'!C34*Assumptions!$F$40/12 | D35: ='Revenue build'!D34*Assumptions!$F$40/12 | E35: ='Revenue build'!E34*Assumptions!$F$40/12 | F35: ='Revenue build'!F34*Assumptions!$F$40/12 | G35: ='Revenue build'!G34*Assumptions!$F$40/12 | H35: ='Revenue build'!H34*Assumptions!$F$40/12 | I35: ='Revenue build'!I34*Assumptions!$F$40/12 | J35: ='Revenue build'!J34*Assumptions!$F$40/12 | ... AL35: ='Revenue build'!AL34*Assumptions!$F$40/12 | AN35: =SUMIF($C$5:$AL$5,AN$5,C35:AL35) | AO35: =SUMIF($C$5:$AL$5,AO$5,C35:AL35) | AP35: =SUMIF($C$5:$AL$5,AP$5,C35:AL35) | AQ35: =SUM(C35:AL35)
A36: E-LEARNING REVENUE | C36: ='Revenue build'!C33+'Revenue build'!C35 | D36: ='Revenue build'!D33+'Revenue build'!D35 | E36: ='Revenue build'!E33+'Revenue build'!E35 | F36: ='Revenue build'!F33+'Revenue build'!F35 | G36: ='Revenue build'!G33+'Revenue build'!G35 | H36: ='Revenue build'!H33+'Revenue build'!H35 | I36: ='Revenue build'!I33+'Revenue build'!I35 | J36: ='Revenue build'!J33+'Revenue build'!J35 | ... AL36: ='Revenue build'!AL33+'Revenue build'!AL35 | AN36: =SUMIF($C$5:$AL$5,AN$5,C36:AL36) | AO36: =SUMIF($C$5:$AL$5,AO$5,C36:AL36) | AP36: =SUMIF($C$5:$AL$5,AP$5,C36:AL36) | AQ36: =SUM(C36:AL36)
A38: MATERNALINK (IN DEVELOPMENT)
A39: Paid pilots started (1/0) | C39: =IF(C3>=Assumptions!$F$44,1,0) | D39: =IF(D3>=Assumptions!$F$44,1,0) | E39: =IF(E3>=Assumptions!$F$44,1,0) | F39: =IF(F3>=Assumptions!$F$44,1,0) | G39: =IF(G3>=Assumptions!$F$44,1,0) | H39: =IF(H3>=Assumptions!$F$44,1,0) | I39: =IF(I3>=Assumptions!$F$44,1,0) | J39: =IF(J3>=Assumptions!$F$44,1,0) | ... AL39: =IF(AL3>=Assumptions!$F$44,1,0) | AN39: =INDEX(C39:AL39,1,12) | AO39: =INDEX(C39:AL39,1,24) | AP39: =INDEX(C39:AL39,1,36) | AQ39: =INDEX(C39:AL39,1,36)
A40: Active paid pilots | B40: count | C40: ='Revenue build'!C39*CHOOSE(C6,Assumptions!$F$45,Assumptions!$F$46,Assumptions!$F$47) | D40: ='Revenue build'!D39*CHOOSE(D6,Assumptions!$F$45,Assumptions!$F$46,Assumptions!$F$47) | E40: ='Revenue build'!E39*CHOOSE(E6,Assumptions!$F$45,Assumptions!$F$46,Assumptions!$F$47) | F40: ='Revenue build'!F39*CHOOSE(F6,Assumptions!$F$45,Assumptions!$F$46,Assumptions!$F$47) | G40: ='Revenue build'!G39*CHOOSE(G6,Assumptions!$F$45,Assumptions!$F$46,Assumptions!$F$47) | H40: ='Revenue build'!H39*CHOOSE(H6,Assumptions!$F$45,Assumptions!$F$46,Assumptions!$F$47) | I40: ='Revenue build'!I39*CHOOSE(I6,Assumptions!$F$45,Assumptions!$F$46,Assumptions!$F$47) | J40: ='Revenue build'!J39*CHOOSE(J6,Assumptions!$F$45,Assumptions!$F$46,Assumptions!$F$47) | ... AL40: ='Revenue build'!AL39*CHOOSE(AL6,Assumptions!$F$45,Assumptions!$F$46,Assumptions!$F$47) | AN40: =AVERAGEIF($C$5:$AL$5,AN$5,C40:AL40) | AO40: =AVERAGEIF($C$5:$AL$5,AO$5,C40:AL40) | AP40: =AVERAGEIF($C$5:$AL$5,AP$5,C40:AL40) | AQ40: =AVERAGE(C40:AL40)
A41: Pilot revenue (pilots × value ÷ 12) | C41: ='Revenue build'!C40*Assumptions!$F$48/12 | D41: ='Revenue build'!D40*Assumptions!$F$48/12 | E41: ='Revenue build'!E40*Assumptions!$F$48/12 | F41: ='Revenue build'!F40*Assumptions!$F$48/12 | G41: ='Revenue build'!G40*Assumptions!$F$48/12 | H41: ='Revenue build'!H40*Assumptions!$F$48/12 | I41: ='Revenue build'!I40*Assumptions!$F$48/12 | J41: ='Revenue build'!J40*Assumptions!$F$48/12 | ... AL41: ='Revenue build'!AL40*Assumptions!$F$48/12 | AN41: =SUMIF($C$5:$AL$5,AN$5,C41:AL41) | AO41: =SUMIF($C$5:$AL$5,AO$5,C41:AL41) | AP41: =SUMIF($C$5:$AL$5,AP$5,C41:AL41) | AQ41: =SUM(C41:AL41)
A42: Licence go-live month (base + delay) | B42: month | C42: =Assumptions!$F$50+Assumptions!$F$51 | D42: =Assumptions!$F$50+Assumptions!$F$51 | E42: =Assumptions!$F$50+Assumptions!$F$51 | F42: =Assumptions!$F$50+Assumptions!$F$51 | G42: =Assumptions!$F$50+Assumptions!$F$51 | H42: =Assumptions!$F$50+Assumptions!$F$51 | I42: =Assumptions!$F$50+Assumptions!$F$51 | J42: =Assumptions!$F$50+Assumptions!$F$51 | ... AL42: =Assumptions!$F$50+Assumptions!$F$51 | AN42: =INDEX(C42:AL42,1,12) | AO42: =INDEX(C42:AL42,1,24) | AP42: =INDEX(C42:AL42,1,36) | AQ42: =INDEX(C42:AL42,1,36)
A43: Licences live (1/0) | C43: =IF(C3>='Revenue build'!C42,1,0) | D43: =IF(D3>='Revenue build'!D42,1,0) | E43: =IF(E3>='Revenue build'!E42,1,0) | F43: =IF(F3>='Revenue build'!F42,1,0) | G43: =IF(G3>='Revenue build'!G42,1,0) | H43: =IF(H3>='Revenue build'!H42,1,0) | I43: =IF(I3>='Revenue build'!I42,1,0) | J43: =IF(J3>='Revenue build'!J42,1,0) | ... AL43: =IF(AL3>='Revenue build'!AL42,1,0) | AN43: =INDEX(C43:AL43,1,12) | AO43: =INDEX(C43:AL43,1,24) | AP43: =INDEX(C43:AL43,1,36) | AQ43: =INDEX(C43:AL43,1,36)
...

Sheet Cost of sales
A1: Cost of sales and gross margin
A2: ="Scenario: "&Assumptions!$D$4&" — all figures GBP, scenario values, not actuals"
A3: Month # | C3: 1 | D3: 2 | E3: 3 | F3: 4 | G3: 5 | H3: 6 | I3: 7 | J3: 8 | K3: 9 | L3: 10 | M3: 11 | N3: 12 | O3: 13 | P3: 14 | Q3: 15 | R3: 16 | S3: 17 | T3: 18 | U3: 19 | V3: 20 | W3: 21 | X3: 22 | Y3: 23 | Z3: 24 | AA3: 25 | AB3: 26 | AC3: 27 | AD3: 28 | AE3: 29 | AF3: 30 | AG3: 31 | AH3: 32 | AI3: 33 | AJ3: 34 | AK3: 35 | AL3: 36
A4: Month | C4: 46388 | D4: 46419 | E4: 46447 | F4: 46478 | G4: 46508 | H4: 46539 | I4: 46569 | J4: 46600 | K4: 46631 | L4: 46661 | M4: 46692 | N4: 46722 | O4: 46753 | P4: 46784 | Q4: 46813 | R4: 46844 | S4: 46874 | T4: 46905 | U4: 46935 | V4: 46966 | W4: 46997 | X4: 47027 | Y4: 47058 | Z4: 47088 | AA4: 47119 | AB4: 47150 | AC4: 47178 | AD4: 47209 | AE4: 47239 | AF4: 47270 | AG4: 47300 | AH4: 47331 | AI4: 47362 | AJ4: 47392 | AK4: 47423 | AL4: 47453 | AN4: FY2027 | AO4: FY2028 | AP4: FY2029 | AQ4: 3-year total
A5: Year | C5: 2027 | D5: 2027 | E5: 2027 | F5: 2027 | G5: 2027 | H5: 2027 | I5: 2027 | J5: 2027 | K5: 2027 | L5: 2027 | M5: 2027 | N5: 2027 | O5: 2028 | P5: 2028 | Q5: 2028 | R5: 2028 | S5: 2028 | T5: 2028 | U5: 2028 | V5: 2028 | W5: 2028 | X5: 2028 | Y5: 2028 | Z5: 2028 | AA5: 2029 | AB5: 2029 | AC5: 2029 | AD5: 2029 | AE5: 2029 | AF5: 2029 | AG5: 2029 | AH5: 2029 | AI5: 2029 | AJ5: 2029 | AK5: 2029 | AL5: 2029 | AN5: 2027 | AO5: 2028 | AP5: 2029
A6: Year index | C6: =C5-2026 | D6: =D5-2026 | E6: =E5-2026 | F6: =F5-2026 | G6: =G5-2026 | H6: =H5-2026 | I6: =I5-2026 | J6: =J5-2026 | ... AL6: =AL5-2026
A7: Advisory direct costs (travel/tools per billable day) | C7: =('Revenue build'!C16+'Revenue build'!C13)*Assumptions!$F$22 | D7: =('Revenue build'!D16+'Revenue build'!D13)*Assumptions!$F$22 | E7: =('Revenue build'!E16+'Revenue build'!E13)*Assumptions!$F$22 | F7: =('Revenue build'!F16+'Revenue build'!F13)*Assumptions!$F$22 | G7: =('Revenue build'!G16+'Revenue build'!G13)*Assumptions!$F$22 | H7: =('Revenue build'!H16+'Revenue build'!H13)*Assumptions!$F$22 | I7: =('Revenue build'!I16+'Revenue build'!I13)*Assumptions!$F$22 | J7: =('Revenue build'!J16+'Revenue build'!J13)*Assumptions!$F$22 | ... AL7: =('Revenue build'!AL16+'Revenue build'!AL13)*Assumptions!$F$22 | AN7: =SUMIF($C$5:$AL$5,AN$5,C7:AL7) | AO7: =SUMIF($C$5:$AL$5,AO$5,C7:AL7) | AP7: =SUMIF($C$5:$AL$5,AP$5,C7:AL7) | AQ7: =SUM(C7:AL7)
A8: Consulting delivery (associates, expenses) | C8: ='Revenue build'!C27*Assumptions!$F$31 | D8: ='Revenue build'!D27*Assumptions!$F$31 | E8: ='Revenue build'!E27*Assumptions!$F$31 | F8: ='Revenue build'!F27*Assumptions!$F$31 | G8: ='Revenue build'!G27*Assumptions!$F$31 | H8: ='Revenue build'!H27*Assumptions!$F$31 | I8: ='Revenue build'!I27*Assumptions!$F$31 | J8: ='Revenue build'!J27*Assumptions!$F$31 | ... AL8: ='Revenue build'!AL27*Assumptions!$F$31 | AN8: =SUMIF($C$5:$AL$5,AN$5,C8:AL8) | AO8: =SUMIF($C$5:$AL$5,AO$5,C8:AL8) | AP8: =SUMIF($C$5:$AL$5,AP$5,C8:AL8) | AQ8: =SUM(C8:AL8)
A9: E-learning platform and payment fees | C9: ='Revenue build'!C36*Assumptions!$F$41 | D9: ='Revenue build'!D36*Assumptions!$F$41 | E9: ='Revenue build'!E36*Assumptions!$F$41 | F9: ='Revenue build'!F36*Assumptions!$F$41 | G9: ='Revenue build'!G36*Assumptions!$F$41 | H9: ='Revenue build'!H36*Assumptions!$F$41 | I9: ='Revenue build'!I36*Assumptions!$F$41 | J9: ='Revenue build'!J36*Assumptions!$F$41 | ... AL9: ='Revenue build'!AL36*Assumptions!$F$41 | AN9: =SUMIF($C$5:$AL$5,AN$5,C9:AL9) | AO9: =SUMIF($C$5:$AL$5,AO$5,C9:AL9) | AP9: =SUMIF($C$5:$AL$5,AP$5,C9:AL9) | AQ9: =SUM(C9:AL9)
A10: MaternaLink pilot delivery | C10: ='Revenue build'!C41*Assumptions!$F$49 | D10: ='Revenue build'!D41*Assumptions!$F$49 | E10: ='Revenue build'!E41*Assumptions!$F$49 | F10: ='Revenue build'!F41*Assumptions!$F$49 | G10: ='Revenue build'!G41*Assumptions!$F$49 | H10: ='Revenue build'!H41*Assumptions!$F$49 | I10: ='Revenue build'!I41*Assumptions!$F$49 | J10: ='Revenue build'!J41*Assumptions!$F$49 | ... AL10: ='Revenue build'!AL41*Assumptions!$F$49 | AN10: =SUMIF($C$5:$AL$5,AN$5,C10:AL10) | AO10: =SUMIF($C$5:$AL$5,AO$5,C10:AL10) | AP10: =SUMIF($C$5:$AL$5,AP$5,C10:AL10) | AQ10: =SUM(C10:AL10)
A11: MaternaLink licence hosting/support | C11: =('Revenue build'!C44*Assumptions!$F$55+'Revenue build'!C46*Assumptions!$F$59)/12 | D11: =('Revenue build'!D44*Assumptions!$F$55+'Revenue build'!D46*Assumptions!$F$59)/12 | E11: =('Revenue build'!E44*Assumptions!$F$55+'Revenue build'!E46*Assumptions!$F$59)/12 | F11: =('Revenue build'!F44*Assumptions!$F$55+'Revenue build'!F46*Assumptions!$F$59)/12 | G11: =('Revenue build'!G44*Assumptions!$F$55+'Revenue build'!G46*Assumptions!$F$59)/12 | H11: =('Revenue build'!H44*Assumptions!$F$55+'Revenue build'!H46*Assumptions!$F$59)/12 | I11: =('Revenue build'!I44*Assumptions!$F$55+'Revenue build'!I46*Assumptions!$F$59)/12 | J11: =('Revenue build'!J44*Assumptions!$F$55+'Revenue build'!J46*Assumptions!$F$59)/12 | ... AL11: =('Revenue build'!AL44*Assumptions!$F$55+'Revenue build'!AL46*Assumptions!$F$59)/12 | AN11: =SUMIF($C$5:$AL$5,AN$5,C11:AL11) | AO11: =SUMIF($C$5:$AL$5,AO$5,C11:AL11) | AP11: =SUMIF($C$5:$AL$5,AP$5,C11:AL11) | AQ11: =SUM(C11:AL11)
A12: TOTAL COST OF SALES | C12: =SUM(C7:C11) | D12: =SUM(D7:D11) | E12: =SUM(E7:E11) | F12: =SUM(F7:F11) | G12: =SUM(G7:G11) | H12: =SUM(H7:H11) | I12: =SUM(I7:I11) | J12: =SUM(J7:J11) | ... AL12: =SUM(AL7:AL11) | AN12: =SUMIF($C$5:$AL$5,AN$5,C12:AL12) | AO12: =SUMIF($C$5:$AL$5,AO$5,C12:AL12) | AP12: =SUMIF($C$5:$AL$5,AP$5,C12:AL12) | AQ12: =SUM(C12:AL12)
A14: Total revenue | C14: ='Revenue build'!C50 | D14: ='Revenue build'!D50 | E14: ='Revenue build'!E50 | F14: ='Revenue build'!F50 | G14: ='Revenue build'!G50 | H14: ='Revenue build'!H50 | I14: ='Revenue build'!I50 | J14: ='Revenue build'!J50 | ... AL14: ='Revenue build'!AL50 | AN14: =SUMIF($C$5:$AL$5,AN$5,C14:AL14) | AO14: =SUMIF($C$5:$AL$5,AO$5,C14:AL14) | AP14: =SUMIF($C$5:$AL$5,AP$5,C14:AL14) | AQ14: =SUM(C14:AL14)
A15: GROSS PROFIT | C15: ='Cost of sales'!C14-'Cost of sales'!C12 | D15: ='Cost of sales'!D14-'Cost of sales'!D12 | E15: ='Cost of sales'!E14-'Cost of sales'!E12 | F15: ='Cost of sales'!F14-'Cost of sales'!F12 | G15: ='Cost of sales'!G14-'Cost of sales'!G12 | H15: ='Cost of sales'!H14-'Cost of sales'!H12 | I15: ='Cost of sales'!I14-'Cost of sales'!I12 | J15: ='Cost of sales'!J14-'Cost of sales'!J12 | ... AL15: ='Cost of sales'!AL14-'Cost of sales'!AL12 | AN15: =SUMIF($C$5:$AL$5,AN$5,C15:AL15) | AO15: =SUMIF($C$5:$AL$5,AO$5,C15:AL15) | AP15: =SUMIF($C$5:$AL$5,AP$5,C15:AL15) | AQ15: =SUM(C15:AL15)
A16: Gross margin % | C16: =IF('Cost of sales'!C14>0,'Cost of sales'!C15/'Cost of sales'!C14,0) | D16: =IF('Cost of sales'!D14>0,'Cost of sales'!D15/'Cost of sales'!D14,0) | E16: =IF('Cost of sales'!E14>0,'Cost of sales'!E15/'Cost of sales'!E14,0) | F16: =IF('Cost of sales'!F14>0,'Cost of sales'!F15/'Cost of sales'!F14,0) | G16: =IF('Cost of sales'!G14>0,'Cost of sales'!G15/'Cost of sales'!G14,0) | H16: =IF('Cost of sales'!H14>0,'Cost of sales'!H15/'Cost of sales'!H14,0) | I16: =IF('Cost of sales'!I14>0,'Cost of sales'!I15/'Cost of sales'!I14,0) | J16: =IF('Cost of sales'!J14>0,'Cost of sales'!J15/'Cost of sales'!J14,0) | ... AL16: =IF('Cost of sales'!AL14>0,'Cost of sales'!AL15/'Cost of sales'!AL14,0) | AN16: =IF(AN14<>0,AN15/AN14,0) | AO16: =IF(AO14<>0,AO15/AO14,0) | AP16: =IF(AP14<>0,AP15/AP14,0) | AQ16: =IF(AQ14<>0,AQ15/AQ14,0)

Sheet Opex
A1: Operating expenses
A2: ="Scenario: "&Assumptions!$D$4&" — all figures GBP, scenario values, not actuals"
A3: Month # | C3: 1 | D3: 2 | E3: 3 | F3: 4 | G3: 5 | H3: 6 | I3: 7 | J3: 8 | K3: 9 | L3: 10 | M3: 11 | N3: 12 | O3: 13 | P3: 14 | Q3: 15 | R3: 16 | S3: 17 | T3: 18 | U3: 19 | V3: 20 | W3: 21 | X3: 22 | Y3: 23 | Z3: 24 | AA3: 25 | AB3: 26 | AC3: 27 | AD3: 28 | AE3: 29 | AF3: 30 | AG3: 31 | AH3: 32 | AI3: 33 | AJ3: 34 | AK3: 35 | AL3: 36
A4: Month | C4: 46388 | D4: 46419 | E4: 46447 | F4: 46478 | G4: 46508 | H4: 46539 | I4: 46569 | J4: 46600 | K4: 46631 | L4: 46661 | M4: 46692 | N4: 46722 | O4: 46753 | P4: 46784 | Q4: 46813 | R4: 46844 | S4: 46874 | T4: 46905 | U4: 46935 | V4: 46966 | W4: 46997 | X4: 47027 | Y4: 47058 | Z4: 47088 | AA4: 47119 | AB4: 47150 | AC4: 47178 | AD4: 47209 | AE4: 47239 | AF4: 47270 | AG4: 47300 | AH4: 47331 | AI4: 47362 | AJ4: 47392 | AK4: 47423 | AL4: 47453 | AN4: FY2027 | AO4: FY2028 | AP4: FY2029 | AQ4: 3-year total
A5: Year | C5: 2027 | D5: 2027 | E5: 2027 | F5: 2027 | G5: 2027 | H5: 2027 | I5: 2027 | J5: 2027 | K5: 2027 | L5: 2027 | M5: 2027 | N5: 2027 | O5: 2028 | P5: 2028 | Q5: 2028 | R5: 2028 | S5: 2028 | T5: 2028 | U5: 2028 | V5: 2028 | W5: 2028 | X5: 2028 | Y5: 2028 | Z5: 2028 | AA5: 2029 | AB5: 2029 | AC5: 2029 | AD5: 2029 | AE5: 2029 | AF5: 2029 | AG5: 2029 | AH5: 2029 | AI5: 2029 | AJ5: 2029 | AK5: 2029 | AL5: 2029 | AN5: 2027 | AO5: 2028 | AP5: 2029
A6: Year index | C6: =C5-2026 | D6: =D5-2026 | E6: =E5-2026 | F6: =F5-2026 | G6: =G5-2026 | H6: =H5-2026 | I6: =I5-2026 | J6: =J5-2026 | ... AL6: =AL5-2026
A7: PEOPLE
A8: Founder salary | C8: ='Headcount'!C21 | D8: ='Headcount'!D21 | E8: ='Headcount'!E21 | F8: ='Headcount'!F21 | G8: ='Headcount'!G21 | H8: ='Headcount'!H21 | I8: ='Headcount'!I21 | J8: ='Headcount'!J21 | ... AL8: ='Headcount'!AL21 | AN8: =SUMIF($C$5:$AL$5,AN$5,C8:AL8) | AO8: =SUMIF($C$5:$AL$5,AO$5,C8:AL8) | AP8: =SUMIF($C$5:$AL$5,AP$5,C8:AL8) | AQ8: =SUM(C8:AL8)
A9: Employee salaries (hires) | C9: ='Headcount'!C31-'Headcount'!C21 | D9: ='Headcount'!D31-'Headcount'!D21 | E9: ='Headcount'!E31-'Headcount'!E21 | F9: ='Headcount'!F31-'Headcount'!F21 | G9: ='Headcount'!G31-'Headcount'!G21 | H9: ='Headcount'!H31-'Headcount'!H21 | I9: ='Headcount'!I31-'Headcount'!I21 | J9: ='Headcount'!J31-'Headcount'!J21 | ... AL9: ='Headcount'!AL31-'Headcount'!AL21 | AN9: =SUMIF($C$5:$AL$5,AN$5,C9:AL9) | AO9: =SUMIF($C$5:$AL$5,AO$5,C9:AL9) | AP9: =SUMIF($C$5:$AL$5,AP$5,C9:AL9) | AQ9: =SUM(C9:AL9)
A10: Employer NI (15% above secondary threshold) | C10: ='Headcount'!C44 | D10: ='Headcount'!D44 | E10: ='Headcount'!E44 | F10: ='Headcount'!F44 | G10: ='Headcount'!G44 | H10: ='Headcount'!H44 | I10: ='Headcount'!I44 | J10: ='Headcount'!J44 | ... AL10: ='Headcount'!AL44 | AN10: =SUMIF($C$5:$AL$5,AN$5,C10:AL10) | AO10: =SUMIF($C$5:$AL$5,AO$5,C10:AL10) | AP10: =SUMIF($C$5:$AL$5,AP$5,C10:AL10) | AQ10: =SUM(C10:AL10)
A11: Employer pension (3% qualifying earnings) | C11: ='Headcount'!C57 | D11: ='Headcount'!D57 | E11: ='Headcount'!E57 | F11: ='Headcount'!F57 | G11: ='Headcount'!G57 | H11: ='Headcount'!H57 | I11: ='Headcount'!I57 | J11: ='Headcount'!J57 | ... AL11: ='Headcount'!AL57 | AN11: =SUMIF($C$5:$AL$5,AN$5,C11:AL11) | AO11: =SUMIF($C$5:$AL$5,AO$5,C11:AL11) | AP11: =SUMIF($C$5:$AL$5,AP$5,C11:AL11) | AQ11: =SUM(C11:AL11)
A12: Employment Allowance credit | C12: ='Headcount'!C59 | D12: ='Headcount'!D59 | E12: ='Headcount'!E59 | F12: ='Headcount'!F59 | G12: ='Headcount'!G59 | H12: ='Headcount'!H59 | I12: ='Headcount'!I59 | J12: ='Headcount'!J59 | ... AL12: ='Headcount'!AL59 | AN12: =SUMIF($C$5:$AL$5,AN$5,C12:AL12) | AO12: =SUMIF($C$5:$AL$5,AO$5,C12:AL12) | AP12: =SUMIF($C$5:$AL$5,AP$5,C12:AL12) | AQ12: =SUM(C12:AL12)
A13: Total employment cost | C13: =SUM(C8:C12) | D13: =SUM(D8:D12) | E13: =SUM(E8:E12) | F13: =SUM(F8:F12) | G13: =SUM(G8:G12) | H13: =SUM(H8:H12) | I13: =SUM(I8:I12) | J13: =SUM(J8:J12) | ... AL13: =SUM(AL8:AL12) | AN13: =SUMIF($C$5:$AL$5,AN$5,C13:AL13) | AO13: =SUMIF($C$5:$AL$5,AO$5,C13:AL13) | AP13: =SUMIF($C$5:$AL$5,AP$5,C13:AL13) | AQ13: =SUM(C13:AL13)
A15: OTHER OPERATING COSTS
A16: Contractors (dev, design, implementation, fractional clinical safety officer) | C16: =CHOOSE(C6,Assumptions!$F$89,Assumptions!$F$90,Assumptions!$F$91) | D16: =CHOOSE(D6,Assumptions!$F$89,Assumptions!$F$90,Assumptions!$F$91) | E16: =CHOOSE(E6,Assumptions!$F$89,Assumptions!$F$90,Assumptions!$F$91) | F16: =CHOOSE(F6,Assumptions!$F$89,Assumptions!$F$90,Assumptions!$F$91) | G16: =CHOOSE(G6,Assumptions!$F$89,Assumptions!$F$90,Assumptions!$F$91) | H16: =CHOOSE(H6,Assumptions!$F$89,Assumptions!$F$90,Assumptions!$F$91) | I16: =CHOOSE(I6,Assumptions!$F$89,Assumptions!$F$90,Assumptions!$F$91) | J16: =CHOOSE(J6,Assumptions!$F$89,Assumptions!$F$90,Assumptions!$F$91) | ... AL16: =CHOOSE(AL6,Assumptions!$F$89,Assumptions!$F$90,Assumptions!$F$91) | AN16: =SUMIF($C$5:$AL$5,AN$5,C16:AL16) | AO16: =SUMIF($C$5:$AL$5,AO$5,C16:AL16) | AP16: =SUMIF($C$5:$AL$5,AP$5,C16:AL16) | AQ16: =SUM(C16:AL16)
A17: Technology (cloud, hosting, messaging, tooling) | C17: =CHOOSE(C6,Assumptions!$F$92,Assumptions!$F$93,Assumptions!$F$94) | D17: =CHOOSE(D6,Assumptions!$F$92,Assumptions!$F$93,Assumptions!$F$94) | E17: =CHOOSE(E6,Assumptions!$F$92,Assumptions!$F$93,Assumptions!$F$94) | F17: =CHOOSE(F6,Assumptions!$F$92,Assumptions!$F$93,Assumptions!$F$94) | G17: =CHOOSE(G6,Assumptions!$F$92,Assumptions!$F$93,Assumptions!$F$94) | H17: =CHOOSE(H6,Assumptions!$F$92,Assumptions!$F$93,Assumptions!$F$94) | I17: =CHOOSE(I6,Assumptions!$F$92,Assumptions!$F$93,Assumptions!$F$94) | J17: =CHOOSE(J6,Assumptions!$F$92,Assumptions!$F$93,Assumptions!$F$94) | ... AL17: =CHOOSE(AL6,Assumptions!$F$92,Assumptions!$F$93,Assumptions!$F$94) | AN17: =SUMIF($C$5:$AL$5,AN$5,C17:AL17) | AO17: =SUMIF($C$5:$AL$5,AO$5,C17:AL17) | AP17: =SUMIF($C$5:$AL$5,AP$5,C17:AL17) | AQ17: =SUM(C17:AL17)
A18: Marketing (content, events, paid tests, demand generation) | C18: =CHOOSE(C6,Assumptions!$F$95,Assumptions!$F$96,Assumptions!$F$97) | D18: =CHOOSE(D6,Assumptions!$F$95,Assumptions!$F$96,Assumptions!$F$97) | E18: =CHOOSE(E6,Assumptions!$F$95,Assumptions!$F$96,Assumptions!$F$97) | F18: =CHOOSE(F6,Assumptions!$F$95,Assumptions!$F$96,Assumptions!$F$97) | G18: =CHOOSE(G6,Assumptions!$F$95,Assumptions!$F$96,Assumptions!$F$97) | H18: =CHOOSE(H6,Assumptions!$F$95,Assumptions!$F$96,Assumptions!$F$97) | I18: =CHOOSE(I6,Assumptions!$F$95,Assumptions!$F$96,Assumptions!$F$97) | J18: =CHOOSE(J6,Assumptions!$F$95,Assumptions!$F$96,Assumptions!$F$97) | ... AL18: =CHOOSE(AL6,Assumptions!$F$95,Assumptions!$F$96,Assumptions!$F$97) | AN18: =SUMIF($C$5:$AL$5,AN$5,C18:AL18) | AO18: =SUMIF($C$5:$AL$5,AO$5,C18:AL18) | AP18: =SUMIF($C$5:$AL$5,AP$5,C18:AL18) | AQ18: =SUM(C18:AL18)
A19: Legal (ongoing contracts, IP, employment) | C19: =CHOOSE(C6,Assumptions!$F$98,Assumptions!$F$99,Assumptions!$F$100) | D19: =CHOOSE(D6,Assumptions!$F$98,Assumptions!$F$99,Assumptions!$F$100) | E19: =CHOOSE(E6,Assumptions!$F$98,Assumptions!$F$99,Assumptions!$F$100) | F19: =CHOOSE(F6,Assumptions!$F$98,Assumptions!$F$99,Assumptions!$F$100) | G19: =CHOOSE(G6,Assumptions!$F$98,Assumptions!$F$99,Assumptions!$F$100) | H19: =CHOOSE(H6,Assumptions!$F$98,Assumptions!$F$99,Assumptions!$F$100) | I19: =CHOOSE(I6,Assumptions!$F$98,Assumptions!$F$99,Assumptions!$F$100) | J19: =CHOOSE(J6,Assumptions!$F$98,Assumptions!$F$99,Assumptions!$F$100) | ... AL19: =CHOOSE(AL6,Assumptions!$F$98,Assumptions!$F$99,Assumptions!$F$100) | AN19: =SUMIF($C$5:$AL$5,AN$5,C19:AL19) | AO19: =SUMIF($C$5:$AL$5,AO$5,C19:AL19) | AP19: =SUMIF($C$5:$AL$5,AP$5,C19:AL19) | AQ19: =SUM(C19:AL19)
A20: Compliance & regulatory (ICO, Cyber Essentials, DTAC/DSPT, clinical safety) | C20: =CHOOSE(C6,Assumptions!$F$101,Assumptions!$F$102,Assumptions!$F$103) | D20: =CHOOSE(D6,Assumptions!$F$101,Assumptions!$F$102,Assumptions!$F$103) | E20: =CHOOSE(E6,Assumptions!$F$101,Assumptions!$F$102,Assumptions!$F$103) | F20: =CHOOSE(F6,Assumptions!$F$101,Assumptions!$F$102,Assumptions!$F$103) | G20: =CHOOSE(G6,Assumptions!$F$101,Assumptions!$F$102,Assumptions!$F$103) | H20: =CHOOSE(H6,Assumptions!$F$101,Assumptions!$F$102,Assumptions!$F$103) | I20: =CHOOSE(I6,Assumptions!$F$101,Assumptions!$F$102,Assumptions!$F$103) | J20: =CHOOSE(J6,Assumptions!$F$101,Assumptions!$F$102,Assumptions!$F$103) | ... AL20: =CHOOSE(AL6,Assumptions!$F$101,Assumptions!$F$102,Assumptions!$F$103) | AN20: =SUMIF($C$5:$AL$5,AN$5,C20:AL20) | AO20: =SUMIF($C$5:$AL$5,AO$5,C20:AL20) | AP20: =SUMIF($C$5:$AL$5,AP$5,C20:AL20) | AQ20: =SUM(C20:AL20)
A21: Insurance (PI, PL, D&O, cyber) | C21: =CHOOSE(C6,Assumptions!$F$104,Assumptions!$F$105,Assumptions!$F$106) | D21: =CHOOSE(D6,Assumptions!$F$104,Assumptions!$F$105,Assumptions!$F$106) | E21: =CHOOSE(E6,Assumptions!$F$104,Assumptions!$F$105,Assumptions!$F$106) | F21: =CHOOSE(F6,Assumptions!$F$104,Assumptions!$F$105,Assumptions!$F$106) | G21: =CHOOSE(G6,Assumptions!$F$104,Assumptions!$F$105,Assumptions!$F$106) | H21: =CHOOSE(H6,Assumptions!$F$104,Assumptions!$F$105,Assumptions!$F$106) | I21: =CHOOSE(I6,Assumptions!$F$104,Assumptions!$F$105,Assumptions!$F$106) | J21: =CHOOSE(J6,Assumptions!$F$104,Assumptions!$F$105,Assumptions!$F$106) | ... AL21: =CHOOSE(AL6,Assumptions!$F$104,Assumptions!$F$105,Assumptions!$F$106) | AN21: =SUMIF($C$5:$AL$5,AN$5,C21:AL21) | AO21: =SUMIF($C$5:$AL$5,AO$5,C21:AL21) | AP21: =SUMIF($C$5:$AL$5,AP$5,C21:AL21) | AQ21: =SUM(C21:AL21)
A22: Software subscriptions | C22: =CHOOSE(C6,Assumptions!$F$107,Assumptions!$F$108,Assumptions!$F$109) | D22: =CHOOSE(D6,Assumptions!$F$107,Assumptions!$F$108,Assumptions!$F$109) | E22: =CHOOSE(E6,Assumptions!$F$107,Assumptions!$F$108,Assumptions!$F$109) | F22: =CHOOSE(F6,Assumptions!$F$107,Assumptions!$F$108,Assumptions!$F$109) | G22: =CHOOSE(G6,Assumptions!$F$107,Assumptions!$F$108,Assumptions!$F$109) | H22: =CHOOSE(H6,Assumptions!$F$107,Assumptions!$F$108,Assumptions!$F$109) | I22: =CHOOSE(I6,Assumptions!$F$107,Assumptions!$F$108,Assumptions!$F$109) | J22: =CHOOSE(J6,Assumptions!$F$107,Assumptions!$F$108,Assumptions!$F$109) | ... AL22: =CHOOSE(AL6,Assumptions!$F$107,Assumptions!$F$108,Assumptions!$F$109) | AN22: =SUMIF($C$5:$AL$5,AN$5,C22:AL22) | AO22: =SUMIF($C$5:$AL$5,AO$5,C22:AL22) | AP22: =SUMIF($C$5:$AL$5,AP$5,C22:AL22) | AQ22: =SUM(C22:AL22)
A23: Travel (UK and Nigeria) | C23: =CHOOSE(C6,Assumptions!$F$110,Assumptions!$F$111,Assumptions!$F$112) | D23: =CHOOSE(D6,Assumptions!$F$110,Assumptions!$F$111,Assumptions!$F$112) | E23: =CHOOSE(E6,Assumptions!$F$110,Assumptions!$F$111,Assumptions!$F$112) | F23: =CHOOSE(F6,Assumptions!$F$110,Assumptions!$F$111,Assumptions!$F$112) | G23: =CHOOSE(G6,Assumptions!$F$110,Assumptions!$F$111,Assumptions!$F$112) | H23: =CHOOSE(H6,Assumptions!$F$110,Assumptions!$F$111,Assumptions!$F$112) | I23: =CHOOSE(I6,Assumptions!$F$110,Assumptions!$F$111,Assumptions!$F$112) | J23: =CHOOSE(J6,Assumptions!$F$110,Assumptions!$F$111,Assumptions!$F$112) | ... AL23: =CHOOSE(AL6,Assumptions!$F$110,Assumptions!$F$111,Assumptions!$F$112) | AN23: =SUMIF($C$5:$AL$5,AN$5,C23:AL23) | AO23: =SUMIF($C$5:$AL$5,AO$5,C23:AL23) | AP23: =SUMIF($C$5:$AL$5,AP$5,C23:AL23) | AQ23: =SUM(C23:AL23)
A24: Operations (co-working, recruitment, in-country field support, misc.) | C24: =CHOOSE(C6,Assumptions!$F$113,Assumptions!$F$114,Assumptions!$F$115) | D24: =CHOOSE(D6,Assumptions!$F$113,Assumptions!$F$114,Assumptions!$F$115) | E24: =CHOOSE(E6,Assumptions!$F$113,Assumptions!$F$114,Assumptions!$F$115) | F24: =CHOOSE(F6,Assumptions!$F$113,Assumptions!$F$114,Assumptions!$F$115) | G24: =CHOOSE(G6,Assumptions!$F$113,Assumptions!$F$114,Assumptions!$F$115) | H24: =CHOOSE(H6,Assumptions!$F$113,Assumptions!$F$114,Assumptions!$F$115) | I24: =CHOOSE(I6,Assumptions!$F$113,Assumptions!$F$114,Assumptions!$F$115) | J24: =CHOOSE(J6,Assumptions!$F$113,Assumptions!$F$114,Assumptions!$F$115) | ... AL24: =CHOOSE(AL6,Assumptions!$F$113,Assumptions!$F$114,Assumptions!$F$115) | AN24: =SUMIF($C$5:$AL$5,AN$5,C24:AL24) | AO24: =SUMIF($C$5:$AL$5,AO$5,C24:AL24) | AP24: =SUMIF($C$5:$AL$5,AP$5,C24:AL24) | AQ24: =SUM(C24:AL24)
A25: Accountancy, payroll, company secretarial | C25: =CHOOSE(C6,Assumptions!$F$116,Assumptions!$F$117,Assumptions!$F$118) | D25: =CHOOSE(D6,Assumptions!$F$116,Assumptions!$F$117,Assumptions!$F$118) | E25: =CHOOSE(E6,Assumptions!$F$116,Assumptions!$F$117,Assumptions!$F$118) | F25: =CHOOSE(F6,Assumptions!$F$116,Assumptions!$F$117,Assumptions!$F$118) | G25: =CHOOSE(G6,Assumptions!$F$116,Assumptions!$F$117,Assumptions!$F$118) | H25: =CHOOSE(H6,Assumptions!$F$116,Assumptions!$F$117,Assumptions!$F$118) | I25: =CHOOSE(I6,Assumptions!$F$116,Assumptions!$F$117,Assumptions!$F$118) | J25: =CHOOSE(J6,Assumptions!$F$116,Assumptions!$F$117,Assumptions!$F$118) | ... AL25: =CHOOSE(AL6,Assumptions!$F$116,Assumptions!$F$117,Assumptions!$F$118) | AN25: =SUMIF($C$5:$AL$5,AN$5,C25:AL25) | AO25: =SUMIF($C$5:$AL$5,AO$5,C25:AL25) | AP25: =SUMIF($C$5:$AL$5,AP$5,C25:AL25) | AQ25: =SUM(C25:AL25)
A26: Legal & IP set-up (one-off) | C26: =IF(C3=1,Assumptions!$F$119,0) | D26: =IF(D3=1,Assumptions!$F$119,0) | E26: =IF(E3=1,Assumptions!$F$119,0) | F26: =IF(F3=1,Assumptions!$F$119,0) | G26: =IF(G3=1,Assumptions!$F$119,0) | H26: =IF(H3=1,Assumptions!$F$119,0) | I26: =IF(I3=1,Assumptions!$F$119,0) | J26: =IF(J3=1,Assumptions!$F$119,0) | ... AL26: =IF(AL3=1,Assumptions!$F$119,0) | AN26: =SUMIF($C$5:$AL$5,AN$5,C26:AL26) | AO26: =SUMIF($C$5:$AL$5,AO$5,C26:AL26) | AP26: =SUMIF($C$5:$AL$5,AP$5,C26:AL26) | AQ26: =SUM(C26:AL26)
A27: E-learning content build (one-off at launch) | C27: =IF(C3=Assumptions!$F$33,Assumptions!$F$42,0) | D27: =IF(D3=Assumptions!$F$33,Assumptions!$F$42,0) | E27: =IF(E3=Assumptions!$F$33,Assumptions!$F$42,0) | F27: =IF(F3=Assumptions!$F$33,Assumptions!$F$42,0) | G27: =IF(G3=Assumptions!$F$33,Assumptions!$F$42,0) | H27: =IF(H3=Assumptions!$F$33,Assumptions!$F$42,0) | I27: =IF(I3=Assumptions!$F$33,Assumptions!$F$42,0) | J27: =IF(J3=Assumptions!$F$33,Assumptions!$F$42,0) | ... AL27: =IF(AL3=Assumptions!$F$33,Assumptions!$F$42,0) | AN27: =SUMIF($C$5:$AL$5,AN$5,C27:AL27) | AO27: =SUMIF($C$5:$AL$5,AO$5,C27:AL27) | AP27: =SUMIF($C$5:$AL$5,AP$5,C27:AL27) | AQ27: =SUM(C27:AL27)
A28: Total other operating costs | C28: =SUM(C16:C27) | D28: =SUM(D16:D27) | E28: =SUM(E16:E27) | F28: =SUM(F16:F27) | G28: =SUM(G16:G27) | H28: =SUM(H16:H27) | I28: =SUM(I16:I27) | J28: =SUM(J16:J27) | ... AL28: =SUM(AL16:AL27) | AN28: =SUMIF($C$5:$AL$5,AN$5,C28:AL28) | AO28: =SUMIF($C$5:$AL$5,AO$5,C28:AL28) | AP28: =SUMIF($C$5:$AL$5,AP$5,C28:AL28) | AQ28: =SUM(C28:AL28)
A30: TOTAL OPERATING EXPENSES | C30: ='Opex'!C13+'Opex'!C28 | D30: ='Opex'!D13+'Opex'!D28 | E30: ='Opex'!E13+'Opex'!E28 | F30: ='Opex'!F13+'Opex'!F28 | G30: ='Opex'!G13+'Opex'!G28 | H30: ='Opex'!H13+'Opex'!H28 | I30: ='Opex'!I13+'Opex'!I28 | J30: ='Opex'!J13+'Opex'!J28 | ... AL30: ='Opex'!AL13+'Opex'!AL28 | AN30: =SUMIF($C$5:$AL$5,AN$5,C30:AL30) | AO30: =SUMIF($C$5:$AL$5,AO$5,C30:AL30) | AP30: =SUMIF($C$5:$AL$5,AP$5,C30:AL30) | AQ30: =SUM(C30:AL30)

Sheet Headcount
A1: Headcount and payroll (employer NI 15% above £5,000; pension 3% of qualifying earnings)
A2: ="Scenario: "&Assumptions!$D$4&" — all figures GBP, scenario values, not actuals"
A3: Month # | C3: 1 | D3: 2 | E3: 3 | F3: 4 | G3: 5 | H3: 6 | I3: 7 | J3: 8 | K3: 9 | L3: 10 | M3: 11 | N3: 12 | O3: 13 | P3: 14 | Q3: 15 | R3: 16 | S3: 17 | T3: 18 | U3: 19 | V3: 20 | W3: 21 | X3: 22 | Y3: 23 | Z3: 24 | AA3: 25 | AB3: 26 | AC3: 27 | AD3: 28 | AE3: 29 | AF3: 30 | AG3: 31 | AH3: 32 | AI3: 33 | AJ3: 34 | AK3: 35 | AL3: 36
A4: Month | C4: 46388 | D4: 46419 | E4: 46447 | F4: 46478 | G4: 46508 | H4: 46539 | I4: 46569 | J4: 46600 | K4: 46631 | L4: 46661 | M4: 46692 | N4: 46722 | O4: 46753 | P4: 46784 | Q4: 46813 | R4: 46844 | S4: 46874 | T4: 46905 | U4: 46935 | V4: 46966 | W4: 46997 | X4: 47027 | Y4: 47058 | Z4: 47088 | AA4: 47119 | AB4: 47150 | AC4: 47178 | AD4: 47209 | AE4: 47239 | AF4: 47270 | AG4: 47300 | AH4: 47331 | AI4: 47362 | AJ4: 47392 | AK4: 47423 | AL4: 47453 | AN4: FY2027 | AO4: FY2028 | AP4: FY2029 | AQ4: 3-year total
A5: Year | C5: 2027 | D5: 2027 | E5: 2027 | F5: 2027 | G5: 2027 | H5: 2027 | I5: 2027 | J5: 2027 | K5: 2027 | L5: 2027 | M5: 2027 | N5: 2027 | O5: 2028 | P5: 2028 | Q5: 2028 | R5: 2028 | S5: 2028 | T5: 2028 | U5: 2028 | V5: 2028 | W5: 2028 | X5: 2028 | Y5: 2028 | Z5: 2028 | AA5: 2029 | AB5: 2029 | AC5: 2029 | AD5: 2029 | AE5: 2029 | AF5: 2029 | AG5: 2029 | AH5: 2029 | AI5: 2029 | AJ5: 2029 | AK5: 2029 | AL5: 2029 | AN5: 2027 | AO5: 2028 | AP5: 2029
A6: Year index | C6: =C5-2026 | D6: =D5-2026 | E6: =E5-2026 | F6: =F5-2026 | G6: =G5-2026 | H6: =H5-2026 | I6: =I5-2026 | J6: =J5-2026 | ... AL6: =AL5-2026
A7: HEADCOUNT FLAGS (1 = employed in month)
A8: Founder | C8: =IF(C3>=Assumptions!$F$68,1,0) | D8: =IF(D3>=Assumptions!$F$68,1,0) | E8: =IF(E3>=Assumptions!$F$68,1,0) | F8: =IF(F3>=Assumptions!$F$68,1,0) | G8: =IF(G3>=Assumptions!$F$68,1,0) | H8: =IF(H3>=Assumptions!$F$68,1,0) | I8: =IF(I3>=Assumptions!$F$68,1,0) | J8: =IF(J3>=Assumptions!$F$68,1,0) | ... AL8: =IF(AL3>=Assumptions!$F$68,1,0) | AN8: =INDEX(C8:AL8,1,12) | AO8: =INDEX(C8:AL8,1,24) | AP8: =INDEX(C8:AL8,1,36) | AQ8: =INDEX(C8:AL8,1,36)
A9: Product lead / CTO | C9: =IF(C3>=Assumptions!$F$70,1,0) | D9: =IF(D3>=Assumptions!$F$70,1,0) | E9: =IF(E3>=Assumptions!$F$70,1,0) | F9: =IF(F3>=Assumptions!$F$70,1,0) | G9: =IF(G3>=Assumptions!$F$70,1,0) | H9: =IF(H3>=Assumptions!$F$70,1,0) | I9: =IF(I3>=Assumptions!$F$70,1,0) | J9: =IF(J3>=Assumptions!$F$70,1,0) | ... AL9: =IF(AL3>=Assumptions!$F$70,1,0) | AN9: =INDEX(C9:AL9,1,12) | AO9: =INDEX(C9:AL9,1,24) | AP9: =INDEX(C9:AL9,1,36) | AQ9: =INDEX(C9:AL9,1,36)
A10: Developer 1 | C10: =IF(C3>=Assumptions!$F$72,1,0) | D10: =IF(D3>=Assumptions!$F$72,1,0) | E10: =IF(E3>=Assumptions!$F$72,1,0) | F10: =IF(F3>=Assumptions!$F$72,1,0) | G10: =IF(G3>=Assumptions!$F$72,1,0) | H10: =IF(H3>=Assumptions!$F$72,1,0) | I10: =IF(I3>=Assumptions!$F$72,1,0) | J10: =IF(J3>=Assumptions!$F$72,1,0) | ... AL10: =IF(AL3>=Assumptions!$F$72,1,0) | AN10: =INDEX(C10:AL10,1,12) | AO10: =INDEX(C10:AL10,1,24) | AP10: =INDEX(C10:AL10,1,36) | AQ10: =INDEX(C10:AL10,1,36)
A11: Developer 2 | C11: =IF(C3>=Assumptions!$F$74,1,0) | D11: =IF(D3>=Assumptions!$F$74,1,0) | E11: =IF(E3>=Assumptions!$F$74,1,0) | F11: =IF(F3>=Assumptions!$F$74,1,0) | G11: =IF(G3>=Assumptions!$F$74,1,0) | H11: =IF(H3>=Assumptions!$F$74,1,0) | I11: =IF(I3>=Assumptions!$F$74,1,0) | J11: =IF(J3>=Assumptions!$F$74,1,0) | ... AL11: =IF(AL3>=Assumptions!$F$74,1,0) | AN11: =INDEX(C11:AL11,1,12) | AO11: =INDEX(C11:AL11,1,24) | AP11: =INDEX(C11:AL11,1,36) | AQ11: =INDEX(C11:AL11,1,36)
A12: Developer 3 | C12: =IF(C3>=Assumptions!$F$76,1,0) | D12: =IF(D3>=Assumptions!$F$76,1,0) | E12: =IF(E3>=Assumptions!$F$76,1,0) | F12: =IF(F3>=Assumptions!$F$76,1,0) | G12: =IF(G3>=Assumptions!$F$76,1,0) | H12: =IF(H3>=Assumptions!$F$76,1,0) | I12: =IF(I3>=Assumptions!$F$76,1,0) | J12: =IF(J3>=Assumptions!$F$76,1,0) | ... AL12: =IF(AL3>=Assumptions!$F$76,1,0) | AN12: =INDEX(C12:AL12,1,12) | AO12: =INDEX(C12:AL12,1,24) | AP12: =INDEX(C12:AL12,1,36) | AQ12: =INDEX(C12:AL12,1,36)
A13: BD / sales lead | C13: =IF(C3>=Assumptions!$F$78,1,0) | D13: =IF(D3>=Assumptions!$F$78,1,0) | E13: =IF(E3>=Assumptions!$F$78,1,0) | F13: =IF(F3>=Assumptions!$F$78,1,0) | G13: =IF(G3>=Assumptions!$F$78,1,0) | H13: =IF(H3>=Assumptions!$F$78,1,0) | I13: =IF(I3>=Assumptions!$F$78,1,0) | J13: =IF(J3>=Assumptions!$F$78,1,0) | ... AL13: =IF(AL3>=Assumptions!$F$78,1,0) | AN13: =INDEX(C13:AL13,1,12) | AO13: =INDEX(C13:AL13,1,24) | AP13: =INDEX(C13:AL13,1,36) | AQ13: =INDEX(C13:AL13,1,36)
A14: Programme manager (Nigeria) | C14: =IF(C3>=Assumptions!$F$80,1,0) | D14: =IF(D3>=Assumptions!$F$80,1,0) | E14: =IF(E3>=Assumptions!$F$80,1,0) | F14: =IF(F3>=Assumptions!$F$80,1,0) | G14: =IF(G3>=Assumptions!$F$80,1,0) | H14: =IF(H3>=Assumptions!$F$80,1,0) | I14: =IF(I3>=Assumptions!$F$80,1,0) | J14: =IF(J3>=Assumptions!$F$80,1,0) | ... AL14: =IF(AL3>=Assumptions!$F$80,1,0) | AN14: =INDEX(C14:AL14,1,12) | AO14: =INDEX(C14:AL14,1,24) | AP14: =INDEX(C14:AL14,1,36) | AQ14: =INDEX(C14:AL14,1,36)
A15: Clinical lead (midwife/obstetrician) | C15: =IF(C3>=Assumptions!$F$82,1,0) | D15: =IF(D3>=Assumptions!$F$82,1,0) | E15: =IF(E3>=Assumptions!$F$82,1,0) | F15: =IF(F3>=Assumptions!$F$82,1,0) | G15: =IF(G3>=Assumptions!$F$82,1,0) | H15: =IF(H3>=Assumptions!$F$82,1,0) | I15: =IF(I3>=Assumptions!$F$82,1,0) | J15: =IF(J3>=Assumptions!$F$82,1,0) | ... AL15: =IF(AL3>=Assumptions!$F$82,1,0) | AN15: =INDEX(C15:AL15,1,12) | AO15: =INDEX(C15:AL15,1,24) | AP15: =INDEX(C15:AL15,1,36) | AQ15: =INDEX(C15:AL15,1,36)
